Workbook

Sheet Main Table
A1: Tab | B1: Label in App | C1: TESTING | D1: Parameter | E1: Text
A2: Stand | B2: Select Stand | C2: TRUE | D2: StandNumber | E2: =VLOOKUP(D2,_helpTextLookup!A:B,2,FALSE) -> Unique identifier of the Stand.
B3: Edit Stand Number | C3: TRUE | D3: StandNumber | E3: =VLOOKUP(D3,_helpTextLookup!A:B,2,FALSE) -> Unique identifier of the Stand.
B4: Comment | C4: TRY | D4: StandComment | E4: =VLOOKUP(D4,_helpTextLookup!A:B,2,FALSE) -> Comments relating to this stand.
B5: Cruise ID | C5: TRUE | D5: CruiseID | E5: =VLOOKUP(D5,_helpTextLookup!A:B,2,FALSE) -> A unique identification number for a given PTA. For example, the two letter county code, followed by the last two digits of the year collected, followed by a four-number unique identifier.
B6: Planner ID | C6: TRUE | D6: PlannerID | E6: =VLOOKUP(D6,_helpTextLookup!A:B,2,FALSE) -> Name or identification number of PTA practitioner.
B7: Area (ha) | C7: TRUE | D7: StandArea | E7: =VLOOKUP(D7,_helpTextLookup!A:B,2,FALSE) -> Total area of Stand, in hectares.
B8: Organization | C8: TRUE | D8: Organization | E8: =VLOOKUP(D8,_helpTextLookup!A:B,2,FALSE) -> Organization name (e.g. company name, etc.)
B9: Location | C9: TRUE | D9: Location | E9: =VLOOKUP(D9,_helpTextLookup!A:B,2,FALSE) -> Description of the location (e.g., nearest community).
A10: Plot | B10: Select Plot | C10: TRUE | D10: PlotNumber | E10: =VLOOKUP(D10,_helpTextLookup!A:B,2,FALSE) -> Unique identifier of the Plot.
B11: Edit Plot Number | C11: TRUE | D11: PlotNumber | E11: =VLOOKUP(D11,_helpTextLookup!A:B,2,FALSE) -> Unique identifier of the Plot.
B12: Comments | C12: TRUE | D12: PlotComments | E12: =VLOOKUP(D12,_helpTextLookup!A:B,2,FALSE) -> Comments relating to this plot.
B13: Easting | C13: TRY | D13: PlotEasting | E13: =VLOOKUP(D13,_helpTextLookup!A:B,2,FALSE) -> Approximate Easting of the plot.
B14: Northing | C14: TRY | D14: PlotNorthing | E14: =VLOOKUP(D14,_helpTextLookup!A:B,2,FALSE) -> Approximate Northing of the plot.
B15: Plot History: Treated | C15: TRY | D15: TreatedGeneral | E15: =VLOOKUP(D15,_helpTextLookup!A:B,2,FALSE) -> Treatment(s) applied to current plot.
B16: Plot History: Planted | C16: TRY | D16: PlantedGeneral | E16: =VLOOKUP(D16,_helpTextLookup!A:B,2,FALSE) -> Plot was planted. Select the type of plantation.
B17: Ecosite Group | C17: TRY | D17: EcositeGroup | E17: =VLOOKUP(D17,_helpTextLookup!A:B,2,FALSE) -> Forest Ecosystem Classification (FEC) Ecosite Group.
B18: Ecodistrict | C18: TRY | D18: Ecodistrict | E18: =VLOOKUP(D18,_helpTextLookup!A:B,2,FALSE) -> The ecodistrict where the PTA is situated. See Nova Scotia’s Ecological Land Classification (ELC) for details. Ecoregion is needed to determine nutrient-sustainable harvest levels, along with the FEC information described below.
B19: Exposure | C19: TRY | D19: Exposure | E19: =VLOOKUP(D19,_helpTextLookup!A:B,2,FALSE) -> Exposure refers to the relative openness of a site to weather conditions, particularly\r\nwind and sun. Exposure can affect moisture conditions on a site and severely impact the height growth of trees.
B20: Soil | C20: TRUE | D20: FECSoil | E20: =VLOOKUP(D20,_helpTextLookup!A:B,2,FALSE) -> The Forest Ecosystem Classification (FEC) soil type, including any phase (e.g., loamy, stony). Record whether the soil type is an inclusion or generally representative of the stand. It is also useful to record whether the soil type was identified through direct observation or was inferred because measurement was not possible (e.g.,frozen-ground conditions).
B21: Vegetation | C21: TRUE | D21: FECVeg | E21: =VLOOKUP(D21,_helpTextLookup!A:B,2,FALSE) -> The Forest Ecosystem Classification (FEC) vegetation type. Record whether the vegetation type is an inclusion or generally representative of the stand. If the vegetation type is within the Planted Forest Group, record whether the plot is located on an Acadian, Maritime Boreal, or Coastal site.
B22: Regen: Softwood LIT Regen Height (2 - 6m) | C22: TRUE | D22: SWLITRegen | E22: =VLOOKUP(D22,_helpTextLookup!A:B,2,FALSE) -> Softwood regeneration height is within the suitable window for pre-commercial thinning.
B23: Regen: Hardwood LIT Regen Height (2 - 6m) | C23: TRUE | D23: HWLITRegen | E23: =VLOOKUP(D23,_helpTextLookup!A:B,2,FALSE) -> Hardwood regeneration height is within the suitable window for pre-commercial thinning.
B24: Regen: Beech Regneration Stocking >25% | C24: TRUE | D24: StockingBeechRegeneration | E24: =VLOOKUP(D24,_helpTextLookup!A:B,2,FALSE) -> The stocking of beech regeneration greater than 25%. The highly shade-tolerant beech seedlings and suckers outcompete other hardwoods but are susceptible to beech bark disease and are not preferred growing stock.
B25: Regen Stocking: All Commercial Species (%) | C25: TRUE | D25: StockingRegenCommercialSpecies | E25: =VLOOKUP(D25,_helpTextLookup!A:B,2,FALSE) -> Percent stocking of all commercial tree species in 10% stocking classes. } ,
B26: Regen Stocking: LIT Species (%) | C26: TRUE | D26: StockingRegenLITSpecies | E26: =VLOOKUP(D26,_helpTextLookup!A:B,2,FALSE) -> Percent stocking of all LIT species in 10% stocking classes.
B27: LIT Seed Tree Stocking (%) | C27: TRUE | D27: StockingLITSeedTree | E27: =VLOOKUP(D27,_helpTextLookup!A:B,2,FALSE) -> Percent stocking of LIT trees of seed-bearing age at 20-m spacing. } ,
B28: Blowdown (%) | C28: TRUE | D28: Blowdown | E28: =VLOOKUP(D28,_helpTextLookup!A:B,2,FALSE) -> Percent blowdown, by basal area. Blowdown includes wind damaged trees that are uprooted, have broken stems, or are leaning at an angle greater than 15o from vertical. } ,
B29: One Cohort Senescent | C29: TRUE | D29: OneCohortSenescent | E29: =VLOOKUP(D29,_helpTextLookup!A:B,2,FALSE) -> At least one cohort is past the onset age of senescence (Table 1). } ,
B30: Uneven Aged | C30: TRUE | D30: UnevenAged | E30: =VLOOKUP(D30,_helpTextLookup!A:B,2,FALSE) -> Includes two-aged, multi-aged, and all-aged stands. } ,
B31: Understory Strata (%) | C31: TRUE | D31: UnderstoryStrata | E31: =VLOOKUP(D31,_helpTextLookup!A:B,2,FALSE) -> Percent cover of woody plants in the understory between 1 and 3 m in height, recorded as either trees or shrubs. } ,
B32: Understory Dominated By (Trees/Woody Shrubs) | C32: TRUE | D32: UnderStoryDominatedBy | E32: =VLOOKUP(D32,_helpTextLookup!A:B,2,FALSE) -> Understory dominated by trees or woody shrubs.
B33: Age Tree | D33: AgeGeneral | E33: =VLOOKUP(D33,_helpTextLookup!A:B,2,FALSE) -> A minimum of one tree must be cored with an increment borer and aged for each PTA plot. If the plot is not suspected to be old growth, the age tree is selected as a codominant tree of average diameter (e.g., the quadratic mean diameter of the plot). The most abundant, merchantable species should be used and LIT species are preferred. If old growth is suspected, the tree selected to age should be from the most dominant LIT/LT species in the plot and should be representative of the top 20% of the basal area.
B34: Age Tree: Species | C34: TRY | D34: AgeTreeSpecies | E34: =VLOOKUP(D34,_helpTextLookup!A:B,2,FALSE) -> Species of the tree selected for aging.
B35: Age Tree: Age | C35: TRY | D35: AgeTreeAge | E35: =VLOOKUP(D35,_helpTextLookup!A:B,2,FALSE) -> The breast height age of the sampled tree.
B36: Age Tree: DBH (cm) | C36: TRY | D36: AgeTreeDBH | E36: =VLOOKUP(D36,_helpTextLookup!A:B,2,FALSE) -> Diameter at 1.3 m of the tree selected for aging.
A37: Living Trees | B37: Include Biodiversity | C37: TRUE | D37: IncludeBiodiversity | E37: =VLOOKUP(D37,_helpTextLookup!A:B,2,FALSE) -> Choosing to include Biodiversity will activate the followoing columns: Cavity, Diversity, Mast.
B38: Number of Trees In Plot | C38: TRY | D38: NumberOfTreesInPlot | E38: =VLOOKUP(D38,_helpTextLookup!A:B,2,FALSE) -> Number of trees in the plot. Update and click 'Refresh' to add/remove trees.
B39: Tree # | C39: TRY | D39: LivingTreeNumber | E39: =VLOOKUP(D39,_helpTextLookup!A:B,2,FALSE) -> Tree Number. If a tree is deleted, trees will automatically be re-numbered to avoid a gap.
B40: Species | C40: TRY | D40: LivingTreeSpecies | E40: =VLOOKUP(D40,_helpTextLookup!A:B,2,FALSE) -> Tree species.
...

Sheet Stand

Sheet Plot

Sheet Live

Sheet Dead

Sheet CWM

Sheet Summary

Sheet _helpTextLookup
A1: AgeGeneral | B1: A minimum of one tree must be cored with an increment borer and aged for each PTA plot. If the plot is not suspected to be old growth, the age tree is selected as a codominant tree of average diameter (e.g., the quadratic mean diameter of the plot). The most abundant, merchantable species should be used and LIT species are preferred. If old growth is suspected, the tree selected to age should be from the most dominant LIT/LT species in the plot and should be representative of the top 20% of the basal area.
A2: AgeTreeAge | B2: The breast height age of the sampled tree.
A3: AgeTreeDBH | B3: Diameter at 1.3 m of the tree selected for aging.
A4: AgeTreeSpecies | B4: Species of the tree selected for aging.
A5: AGS | B5: Trees are acceptable or unacceptable growing stock, based on the definitions in Appendix 1 of the SGEM.
A6: Blowdown | B6: Percent blowdown, by basal area. Blowdown includes wind damaged trees that are uprooted, have broken stems, or are leaning at an angle greater than 15o from vertical. } ,
A7: Cavity | B7: Live or dead trees that contain hollows (or cavities) in the trunk or limbs, or that show signs of decay that may lead to the formation of cavities that would be used by wildlife for nesting and reproduction. This includes large trees with cavities at the base that will provide den and overwintering sites for mammals.
A8: CWMSpecisGroup | B8: Softwood (SW), hardwood (HW), or unknown species.
A9: CWMTransectDirection | B9: Direction of the transect used to measure coarse woody material.
A10: CWMTransectLength | B10: Length of the transect used to measure coarse woody material.
A11: CruiseID | B11: A unique identification number for a given PTA. For example, the two letter county code, followed by the last two digits of the year collected, followed by a four-number unique identifier.
A12: CWMCavity | B12: Coarse Woody Material pieces that contain cavities.
... A76: CWMCavity | B76: Coarse Woody Material pieces that contain cavities.
